Workbook
Name AG: Premissas!$K$111
Name DOIS: Legenda!$F$53:$F$64
Name PG: Legenda!$C$41:$C$45
Name Salário_Base: 'Recursos Humanos'!#REF!
Name Salário_Base: 'Recursos Humanos'!#REF!
Name Salário_Base: 'Recursos Humanos'!#REF!
Name Salário_Base: 'Recursos Humanos'!#REF!
Name Salário_Base: '[1]Recursos Humanos'!#REF!
Name Salário_Base: 'Recursos Humanos'!#REF!
Name UM: Legenda!$F$53:$F$56

Sheet Legenda
C6: Legenda Básica:
B8: 0 | C8: Indica células para Input de Informações
B10: 0 | C10: Indica células de Output de Informações (não alterar conteúdo em nenhuma hipótese)
B12: 0 | C12: Indica células de Output de Informações. Permite inserir dados para usar como um "atalho" ou simulação, porém a fórmula contida será perdida.
C15: Principais Índices Financeiros:
E16: Franqueado | J16: Franqueadora
C17: Taxa de Retorno (IRR/TIR) | E17: =IRR('Fluxo de Caixa'!H95:BP95) -> 0.076826772 | F17: a.m. | G17: =((1+E17)^(12))-1 -> 1.4308051 | H17: a.a. | J17: =IRR('DRE Franqueadora'!D60:BL60) -> 0.045595776 | K17: a.m. | L17: =((1+J17)^(12))-1 -> 0.70752016 | M17: a.a.
C19: Necessidade de Capital Total | E19: =-'Investimento Inicial'!F38 -> -65321.93
C21: Capital de Giro | E21: =-'Investimento Inicial'!F33 -> -16843.93
C23: Investimento Inicial | E23: =E19-E21 -> -48478
C27: Gerenciamento de Caixa:
C29: Prazo Médio de Estoque | F29: =IF(M29=0,0,K29/M29*30) -> 0 | G29: dias | J29: estoque médio (R$) | K29: 0 | L29: CMV mensal (R$) | M29: 0
C31: Prazo Médio de Recebimento* | F31: =30*DRE!$D$20 -> 0 | G31: dias
C33: Prazo Médio de Pagto | F33: 0 | G33: dias | I33: maximo 90 dias | L33: Prazo Médio CMV | N33: ='Fluxo de Caixa'!F13 -> 0 | P33: Recursos Humanos | R33: ='Fluxo de Caixa'!F26 -> 0 | T33: Despesas Fixas | V33: ='Fluxo de Caixa'!F31 -> 0
C35: Ciclo de Caixa | F35: =F29+F31-F33 -> 0 | G35: dias
C37: *Recebíveis
E39: Check
C40: Percentual à Vista/a Prazo | D40: =SUM(D41:D45) -> 1 | E40: =IF(D40=1,"ok","ERRO") -> ok
C41: (-) Cartão de Crédito | D41: 0
C42: (-) Cartão de Débito | D42: 0
C43: À vista (dinheiro) | D43: 0
C44: PIX | D44: 0.98
C45: Boleto | D45: 0.02
C46: (-) Comissão
D47: À vista | E47: 2x | F47: 3x | G47: 4x | H47: 5x | I47: 6x | J47: 7x | K47: 8x | L47: 9x | M47: 10x | N47: 11x | O47: 12x
C48: Parcelamento Crédito/Alimentação | D48: 1 | E48: 0 | F48: 0 | G48: 0 | H48: 0 | I48: 0 | J48: 0 | K48: 0 | L48: 0 | M48: 0 | N48: 0 | O48: 0 | P48: =SUM(D48:O48) -> 1 | Q48: =IF(P48=1,"ok","ERRO") -> ok
C52: Impostos: | F52: Unidade de Medida
F53: m²
C54: Regime Tributário Franqueado: | F54: Unitário | R54: Simples Nacional - Anexo 1 | S54: Anexo I
F55: Diária | R55: Simples Nacional - Anexo 2 | S55: Anexo II
C56: Simples Nacional - Anexo 4 | F56: Empreitada | R56: Simples Nacional - Anexo 3 | S56: Anexo III
F57: Conjunto | R57: Simples Nacional - Anexo 4 | S57: Anexo IV
C58: Lucro Presumido - Serviços | F58: Kit | R58: Simples Nacional - Anexo 5 | S58: Anexo V
F59: Pacote | R59: Lucro Presumido - Comércio
F60: Saco | R60: Lucro Presumido - Industria
C61: Regime Tributário Franqueadora: | F61: Fardo | R61: Lucro Presumido - Serviços
F62: Milheiro
C63: Simples Nacional - Anexo 5 | F63: Quilo
F64: Caixa
C65: Lucro Presumido - Serviços

Sheet Dashboard Franqueado
J2: SIMULAÇÃO DOS RESULTADOS DO FRANQUEADO
J4: VPL | K4: Taxa VPL | L4: Payback | N4: Capital de giro | R4: Investimento | V4: Necessidade de Capital | X4: TIR (Taxa de Retorno)
J5: ='Fluxo de Caixa'!I112 -> 400845.73 | K5: ='Fluxo de Caixa'!G100 -> 0.12 | L5: ='Fluxo de Caixa'!I111 -> 17 | M5: meses | O5: =Legenda!E21 -> -16843.93 | R5: =Legenda!E23 -> -48478 | V5: =Legenda!E19 -> -65321.93 | X5: =Legenda!G17 -> 1.4308051 | Y5: a.a.
N43: O lucro líquido do franqueado (média mensal), de acordo com as projeções, será de:
N44: Ano 1 | O44: =BA81/12 -> 68.945445 | P44: - com uma lucratividade neste período de | T44: =BA82 -> 0.0016681467 | U44: - com uma rentabilidade neste período de | X44: =O44/'Investimento Inicial'!$F$37 -> 0.0014222007
N45: Ano 2 | O45: =BB81/12 -> 8918.9261 | P45: - com uma lucratividade neste período de | T45: =BB82 -> 0.11235737 | U45: - com uma rentabilidade neste período de | X45: =O45/'Investimento Inicial'!$F$37 -> 0.18397884
N46: Ano 3 | O46: =BC81/12 -> 12330.981 | P46: - com uma lucratividade neste período de | T46: =BC82 -> 0.12963106 | U46: - com uma rentabilidade neste período de | X46: =O46/'Investimento Inicial'!$F$37 -> 0.25436241
N47: Ano 4 | O47: =BD81/12 -> 14206.102 | P47: - com uma lucratividade neste período de | T47: =BD82 -> 0.13770591 | U47: - com uma rentabilidade neste período de | X47: =O47/'Investimento Inicial'!$F$37 -> 0.29304225
N48: Ano 5 | O48: =BE81/12 -> 16641.284 | P48: - com uma lucratividade neste período de | T48: =BE82 -> 0.1470313 | U48: - com uma rentabilidade neste período de | X48: =O48/'Investimento Inicial'!$F$37 -> 0.34327496
AZ59: TABELA DADOS BASE PARA GRÁFICOS
BB62: =(BB65/BA65)-1 -> 0.9206121 | BC62: =(BC65/BB65)-1 -> 0.19833303 | BD62: =(BD65/BC65)-1 -> 0.084510694 | BE62: =(BE65/BD65)-1 -> 0.097121284
AZ63: Média Fat.Bruto Mensal vs Média Receita Líq
BA64: Ano 1 | BB64: Ano 2 | BC64: Ano 3 | BD64: Ano 4 | BE64: Ano 5 | BF64: Ano 6 | BG64: Ano 7 | BH64: Ano 8 | BI64: Ano 9 | BJ64: Ano 10
AZ65: Faturamento Bruto | BA65: =DRE!BQ5/12 -> 41330.565 | BB65: =DRE!BR5/12 -> 79379.984 | BC65: =DRE!BS5/12 -> 95123.657 | BD65: =DRE!BT5/12 -> 103162.62 | BE65: =DRE!BU5/12 -> 113181.91 | BF65: =DRE!#REF!/12 -> #REF! | BG65: =DRE!#REF!/12 -> #REF! | BH65: =DRE!#REF!/12 -> #REF! | BI65: =DRE!#REF!/12 -> #REF! | BJ65: =DRE!#REF!/12 -> #REF!
AZ66: Receita Liquida | BA66: =DRE!BQ13/12 -> 38859.53 | BB66: =DRE!BR13/12 -> 72156.874 | BC66: =DRE!BS13/12 -> 85310.251 | BD66: =DRE!BT13/12 -> 92159.444 | BE66: =DRE!BU13/12 -> 100794.01 | BF66: =DRE!#REF!/12 -> #REF! | BG66: =DRE!#REF!/12 -> #REF! | BH66: =DRE!#REF!/12 -> #REF! | BI66: =DRE!#REF!/12 -> #REF! | BJ66: =DRE!#REF!/12 -> #REF!
BA69: Ano 1 | BB69: Ano 2 | BC69: Ano 3 | BD69: Ano 4 | BE69: Ano 5 | BF69: Ano 6 | BG69: Ano 7 | BH69: Ano 8 | BI69: Ano 9 | BJ69: Ano 10
AZ70: Lucro Bruto | BA70: =DRE!BQ28 -> 199114.62 | BB70: =DRE!BR28 -> 352695.44 | BC70: =DRE!BS28 -> 408754.02 | BD70: =DRE!BT28 -> 438972.89 | BE70: =DRE!BU28 -> 477813.58 | BF70: =DRE!#REF! -> #REF! | BG70: =DRE!#REF! -> #REF! | BH70: =DRE!#REF! -> #REF! | BI70: =DRE!#REF! -> #REF! | BJ70: =DRE!#REF! -> #REF!
AZ71: Média mensal de Lucro bruto | BA71: =BA70/12 -> 16592.885 | BB71: =BB70/12 -> 29391.286 | BC71: =BC70/12 -> 34062.835 | BD71: =BD70/12 -> 36581.074 | BE71: =BE70/12 -> 39817.798 | BF71: =BF70/12 -> #REF! | BG71: =BG70/12 -> #REF! | BH71: =BH70/12 -> #REF! | ... BJ71: =BJ70/12 -> #REF!
AZ72: % | BA72: =DRE!BQ30 -> 0.40146765 | BB72: =DRE!BR30 -> 0.37026068 | BC72: =DRE!BS30 -> 0.35809005 | BD72: =DRE!BT30 -> 0.3545962 | BE72: =DRE!BU30 -> 0.35180355 | BF72: =DRE!#REF! -> #REF! | BG72: =DRE!#REF! -> #REF! | BH72: =DRE!#REF! -> #REF! | BI72: =DRE!#REF! -> #REF! | BJ72: =DRE!#REF! -> #REF!
AZ74: Lucro liquido médio mensal vs lucratividade
BA75: Ano 1 | BB75: Ano 2 | BC75: Ano 3 | BD75: Ano 4 | BE75: Ano 5 | BF75: Ano 6 | BG75: Ano 7 | BH75: Ano 8 | BI75: Ano 9 | BJ75: Ano 10
AZ76: % | BA76: =DRE!BQ115 -> 0.0016681467 | BB76: =DRE!BR115 -> 0.11235737 | BC76: =DRE!BS115 -> 0.12963106 | BD76: =DRE!BT115 -> 0.13770591 | BE76: =DRE!BU115 -> 0.1470313 | BF76: =DRE!#REF! -> #REF! | BG76: =DRE!#REF! -> #REF! | BH76: =DRE!#REF! -> #REF! | BI76: =DRE!#REF! -> #REF! | BJ76: =DRE!#REF! -> #REF!
AZ77: Lucro liquido anual | BA77: =DRE!BQ87 -> 827.34533 | BB77: =DRE!BR84 -> 107027.11 | BC77: =DRE!BS87 -> 147971.77 | BD77: =DRE!BT87 -> 170473.23 | BE77: =DRE!BU87 -> 199695.4 | BF77: =DRE!#REF! -> #REF! | BG77: =DRE!#REF! -> #REF! | BH77: =DRE!#REF! -> #REF! | BI77: =DRE!#REF! -> #REF! | BJ77: =DRE!#REF! -> #REF!
BA80: Ano 1 | BB80: Ano 2 | BC80: Ano 3 | BD80: Ano 4 | BE80: Ano 5 | BF80: Ano 6 | BG80: Ano 7 | BH80: Ano 8 | BI80: Ano 9 | BJ80: Ano 10
AZ81: Lucro Liquido operacional anual | BA81: =DRE!BQ84 -> 827.34533 | BB81: =DRE!BR84 -> 107027.11 | BC81: =DRE!BS84 -> 147971.77 | BD81: =DRE!BT84 -> 170473.23 | BE81: =DRE!BU84 -> 199695.4 | BF81: =DRE!#REF! -> #REF! | BG81: =DRE!#REF! -> #REF! | BH81: =DRE!#REF! -> #REF! | BI81: =DRE!#REF! -> #REF! | BJ81: =DRE!#REF! -> #REF!
AZ82: % | BA82: =BA76 -> 0.0016681467 | BB82: =BB76 -> 0.11235737 | BC82: =BC76 -> 0.12963106 | BD82: =BD76 -> 0.13770591 | BE82: =BE76 -> 0.1470313 | BF82: =BF76 -> #REF! | BG82: =BG76 -> #REF! | BH82: =BH76 -> #REF! | ... BJ82: =BJ76 -> #REF!
BA85: Mês
BA86: 1 | BB86: 2 | BC86: 3 | BD86: 4 | BE86: 5 | BF86: 6 | BG86: 7 | BH86: 8 | BI86: 9 | BJ86: 10 | BK86: 11 | BL86: 12 | BM86: 13 | BN86: 14 | BO86: 15 | BP86: 16 | BQ86: 17 | BR86: 18 | BS86: 19 | BT86: 20 | BU86: 21 | BV86: 22 | BW86: 23 | BX86: 24 | BY86: 25 | BZ86: 26 | CA86: 27 | CB86: 28 | CC86: 29 | CD86: 30 | CE86: 31 | CF86: 32 | CG86: 33 | CH86: 34 | CI86: 35 | CJ86: 36 | CK86: 37 | CL86: 38 | CM86: 39 | CN86: 40 | CO86: 41 | CP86: 42 | CQ86: 43 | CR86: 44 | CS86: 45 | CT86: 46 | CU86: 47 | CV86: 48 | CW86: 49 | CX86: 50 | CY86: 51 | CZ86: 52 | DA86: 53 | DB86: 54 | DC86: 55 | DD86: 56 | DE86: 57 | DF86: 58 | DG86: 59 | DH86: 60 | DI86: 61 | DJ86: 62 | DK86: 63 | DL86: 64 | DM86: 65 | DN86: 66 | DO86: 67 | DP86: 68 | DQ86: 69 | DR86: 70 | DS86: 71 | DT86: 72 | DU86: 73 | DV86: 74 | DW86: 75 | DX86: 76 | DY86: 77 | DZ86: 78 | EA86: 79 | EB86: 80 | EC86: 81 | ED86: 82 | EE86: 83 | EF86: 84 | EG86: 85 | EH86: 86 | EI86: 87 | EJ86: 88 | EK86: 89 | EL86: 90 | EM86: 91 | EN86: 92 | EO86: 93 | EP86: 94 | EQ86: 95 | ER86: 96 | ES86: 97 | ET86: 98 | EU86: 99 | EV86: 100 | EW86: 101 | EX86: 102 | EY86: 103 | EZ86: 104 | FA86: 105 | FB86: 106 | FC86: 107 | FD86: 108 | FE86: 109 | FF86: 110 | FG86: 111 | FH86: 112 | FI86: 113 | FJ86: 114 | FK86: 115 | FL86: 116 | FM86: 117 | FN86: 118 | FO86: 119 | FP86: 120
AZ87: Fluxo caixa acumulado | BA87: ='Fluxo de Caixa'!I96 -> -48478 | BB87: ='Fluxo de Caixa'!J96 -> -59140.227 | BC87: ='Fluxo de Caixa'!K96 -> -69030.037 | BD87: ='Fluxo de Caixa'!L96 -> -75773.26 | BE87: ='Fluxo de Caixa'!M96 -> -79403.253 | BF87: ='Fluxo de Caixa'!N96 -> -80202.801 | BG87: ='Fluxo de Caixa'!O96 -> -78320.089 | BH87: ='Fluxo de Caixa'!P96 -> -74034.977 | ... DH87: ='Fluxo de Caixa'!BP96 -> 600441.94 | DI87: ='Fluxo de Caixa'!#REF! -> #REF! | DJ87: ='Fluxo de Caixa'!#REF! -> #REF! | DK87: ='Fluxo de Caixa'!#REF! -> #REF! | DL87: ='Fluxo de Caixa'!#REF! -> #REF! | DM87: ='Fluxo de Caixa'!#REF! -> #REF! | DN87: ='Fluxo de Caixa'!#REF! -> #REF! | DO87: ='Fluxo de Caixa'!#REF! -> #REF! | DP87: ='Fluxo de Caixa'!#REF! -> #REF! | ... FP87: ='Fluxo de Caixa'!#REF! -> #REF!
AZ92: Evolução Rentabilidade
BA93: Ano 1 | BB93: Ano 2 | BC93: Ano 3 | BD93: Ano 4 | BE93: Ano 5 | BF93: Ano 6 | BG93: Ano 7 | BH93: Ano 8 | BI93: Ano 9 | BJ93: Ano 10
AZ94: % | BA94: =-BA95/$R$5 -> 0.017066408 | BB94: =-BB95/$R$5 -> 2.2077461 | BC94: =-BC95/$R$5 -> 3.0523489 | BD94: =-BD95/$R$5 -> 3.5165071 | BE94: =-BE95/$R$5 -> 4.1192995 | BF94: =-BF95/$R$5 -> #REF! | BG94: =-BG95/$R$5 -> #REF! | BH94: =-BH95/$R$5 -> #REF! | ... BJ94: =-BJ95/$R$5 -> #REF!
AZ95: Lucro liquido anual | BA95: =BA77 -> 827.34533 | BB95: =BB77 -> 107027.11 | BC95: =BC77 -> 147971.77 | BD95: =BD77 -> 170473.23 | BE95: =BE77 -> 199695.4 | BF95: =BF77 -> #REF! | BG95: =BG77 -> #REF! | BH95: =BH77 -> #REF! | ... BJ95: =BJ77 -> #REF!

Sheet Investimento Inicial
B1: SIMULAÇÃO DE INVESTIMENTO INICIAL
B2: Projeção para Franquia Home Office | C2: ='Distribuição de Modelos'!E32 -> 171609 | D2: Habitantes
B3: Estimativa de Investimento Inicial (em R$) | C3: Quantidade | D3: Unidade de Medida | E3: Valor Unitário | F3: Total | G3: %
B4: 1. Reforma e Adaptação Visual | F4: =SUM(F5:F5) -> 0 | G4: =F4/$F$37 -> 0
F5: =IF(D5="Empreitada",E5,E5*C5) -> 0 | G5: =F5/$F$37 -> 0
B6: 2. Máquinas e Equipamentos | F6: =SUM(F7:F9) -> 3080 | G6: =F6/$F$37 -> 0.063533974
B7: Notebook I3 - 8100, SSD 256 GB, 8 GB RAM (Caso tenha não não é necessário) | C7: 1 | D7: Unitário | E7: 2000 | F7: =IF(D7="Empreitada",E7,E7*C7) -> 2000 | G7: =F7/$F$37 -> 0.041255827
B8: Celular (Pode utilizar o pessoal apenas precisa acesso ao WhatsApp Business) | C8: 1 | D8: Unitário | E8: 700 | F8: =IF(D8="Empreitada",E8,E8*C8) -> 700 | G8: =F8/$F$37 -> 0.01443954
B9: Impressora (Caso tenha não é necessário) | C9: 1 | D9: Unitário | E9: 380 | F9: =IF(D9="Empreitada",E9,E9*C9) -> 380 | G9: =F9/$F$37 -> 0.0078386072
B10: 3. Mobiliário | F10: =SUM(F11:F11) -> 0 | G10: =F10/$F$37 -> 0
F11: =IF(D11="Empreitada",E11,E11*C11) -> 0 | G11: =F11/$F$37 -> 0
B12: 4. Utensílios | F12: =SUM(F13:F13) -> 0 | G12: =F12/$F$37 -> 0
F13: =E13*C13 -> 0 | G13: =F13/$F$37 -> 0
B14: 5. Estoque Inicial/Embalagens | F14: =SUM(F15:F15) -> 100 | G14: =F14/$F$37 -> 0.0020627914
B15: Material para Escritório | C15: 1 | D15: Unitário | E15: 100 | F15: =IF(D15="Empreitada",E15,E15*C15) -> 100 | G15: =F15/$F$37 -> 0.0020627914
B16: 6. Treinamento | F16: =SUM(F17:F17) -> 0 | G16: =F16/$F$37 -> 0
F17: =IF(D17="Empreitada",E17,E17*C17) -> 0 | G17: =F17/$F$37 -> 0
B18: 7. Marketing de Inauguração | F18: =SUM(F19:F22) -> 7700 | G18: =F18/$F$37 -> 0.15883494
B19: Tráfego Pago | C19: 1 | D19: Unitário | E19: 5000 | F19: =IF(D19="Empreitada",E19,E19*C19) -> 5000 | G19: =F19/$F$37 -> 0.10313957
B20: Agência Marketing | C20: 1 | D20: Unitário | E20: 1200 | F20: =IF(D20="Empreitada",E20,E20*C20) -> 1200 | G20: =F20/$F$37 -> 0.024753496
B21: Equipe para distrubuir panfletos | C21: 1 | D21: Unitário | E21: 1000 | F21: =IF(D21="Empreitada",E21,E21*C21) -> 1000 | G21: =F21/$F$37 -> 0.020627914
B22: Panfletos | C22: 1 | D22: Unitário | E22: 500 | F22: =IF(D22="Empreitada",E22,E22*C22) -> 500 | G22: =F22/$F$37 -> 0.010313957
B23: 8. Abertura de Empresa | F23: =SUM(F24:F28) -> 1998 | G23: =F23/$F$37 -> 0.041214572
B24: Abertura CNPJ | C24: 1 | D24: Unitário | E24: 1200 | F24: =IF(D24="Empreitada",E24,E24*C24) -> 1200 | G24: =F24/$F$38 -> 0.018370553
B25: Alvará de funcionamento | C25: 1 | D25: Unitário | E25: 300 | F25: =IF(D25="Empreitada",E25,E25*C25) -> 300 | G25: =F25/$F$37 -> 0.0061883741
B26: Certificado digital | C26: 1 | D26: Unitário | E26: 180 | F26: =IF(D26="Empreitada",E26,E26*C26) -> 180 | G26: =F26/$F$37 -> 0.0037130245
B27: Junta comercial | C27: 1 | D27: Unitário | E27: 168 | F27: =IF(D27="Empreitada",E27,E27*C27) -> 168 | G27: =F27/$F$37 -> 0.0034654895
B28: Cartório | C28: 1 | D28: Unitário | E28: 150 | F28: =IF(D28="Empreitada",E28,E28*C28) -> 150 | G28: =F28/$F$37 -> 0.0030941871
B29: 9. Outros | F29: =SUM(F30:F31) -> 600 | G29: =F29/$F$37 -> 0.012376748
B30: Uniformes | C30: 15 | D30: Unitário | E30: 40 | F30: =IF(D30="Empreitada",E30,E30*C30) -> 600 | G30: =F30/$F$37 -> 0.012376748
B31: Implantação do Sistema de Gestão (Em Desenvolvimento) | C31: 1 | D31: Unitário | F31: =IF(D31="Empreitada",E31,E31*C31) -> 0 | G31: =F31/$F$37 -> 0
B32: 10. Taxa de Franquia | F32: =Premissas!G25 -> 35000 | G32: =F32/$F$37 -> 0.72197698
B33: 11. Capital de Giro | F33: =2*('Despesas Mensais'!D41+'Recursos Humanos'!N54) -> 16843.93 | G33: =F33/$F$37 -> 0.34745513
B35: TOTAL MONTAGEM LOJA | F35: =SUM(F4,F6,F10,F12,F14,F23,F29) -> 5778 | G35: =F35/$F$37 -> 0.11918809
B36: TOTAL MONTAGEM LOJA + TREINAMENTO + MKT INAUGURAÇÃO | F36: =F35+F16+F18 -> 13478 | G36: =F36/$F$37 -> 0.27802302
B37: TOTAL MONTAGEM LOJA + TREINAMENTO + MKT INAUGURAÇÃO + TAXA DE FRANQUIA | F37: =F36+F32 -> 48478 | G37: =F37/$F$37 -> 1
B38: TOTAL MONTAGEM LOJA + TREINAMENTO + MKT INAUGURAÇÃO + TAXA DE FRANQUIA + GIRO = NECESSIDADE DE CAPITAL | F38: =F37+F33 -> 65321.93 | G38: =F38/$F$38 -> 1
B41: OBSERVAÇÃO
B43: Devido as despesas mensais e folha de pagamento ter um custo relativamente baixo, por precaução, será considerado como necessidade de capital de giro o valor correspondente a 2 (duas) vezes o total gasto da folha de pagamento mais as despesas mensais.

Sheet Despesas Mensais
B1: SIMULAÇÃO DE CUSTOS E DESPESAS MENSAIS
B2: Valores mensais com reajustes anuais | C2: Variável (*)
B3: Descrição | D3: Ano 1 | E3: Ano 2 | F3: Ano 3 | G3: Ano 4 | H3: Ano 5
B4: % Performance Anual | D4: 0.6 | E4: =('Dashboard Franqueado'!BB65-'Dashboard Franqueado'!BA65)/'Dashboard Franqueado'!BA65 -> 0.9206121 | F4: =('Dashboard Franqueado'!BC65-'Dashboard Franqueado'!BB65)/'Dashboard Franqueado'!BB65 -> 0.19833303 | G4: =('Dashboard Franqueado'!BD65-'Dashboard Franqueado'!BC65)/'Dashboard Franqueado'!BC65 -> 0.084510694 | H4: =('Dashboard Franqueado'!BE65-'Dashboard Franqueado'!BD65)/'Dashboard Franqueado'!BD65 -> 0.097121284
B5: Ocupação
B6: Aluguel XX m² | D6: 0 | E6: =IFERROR(IF($C6="",$D6,(D6*E$4)+D6),"") -> 0 | F6: =IFERROR(IF($C6="",$D6,(E6*F$4)+E6),"") -> 0 | G6: =IFERROR(IF($C6="",$D6,(F6*G$4)+F6),"") -> 0 | H6: =IFERROR(IF($C6="",$D6,(G6*H$4)+G6),"") -> 0
B7: IPTU | D7: 0 | E7: =IFERROR(IF($C7="",$D7,(D7*E$4)+D7),"") -> 0 | F7: =IFERROR(IF($C7="",$D7,(E7*F$4)+E7),"") -> 0 | G7: =IFERROR(IF($C7="",$D7,(F7*G$4)+F7),"") -> 0 | H7: =IFERROR(IF($C7="",$D7,(G7*H$4)+G7),"") -> 0
B8: Condomínio | D8: 0 | E8: =IFERROR(IF($C8="",$D8,(D8*E$4)+D8),"") -> 0 | F8: =IFERROR(IF($C8="",$D8,(E8*F$4)+E8),"") -> 0 | G8: =IFERROR(IF($C8="",$D8,(F8*G$4)+F8),"") -> 0 | H8: =IFERROR(IF($C8="",$D8,(G8*H$4)+G8),"") -> 0
B9: Utilidades
B10: Água | D10: 0 | E10: =IFERROR(IF($C10="",$D10,(D10*E$4)+D10),"") -> 0 | F10: =IFERROR(IF($C10="",$D10,(E10*F$4)+E10),"") -> 0 | G10: =IFERROR(IF($C10="",$D10,(F10*G$4)+F10),"") -> 0 | H10: =IFERROR(IF($C10="",$D10,(G10*H$4)+G10),"") -> 0
B11: Energia Elétrica | D11: 0 | E11: =IFERROR(IF($C11="",$D11,(D11*E$4)+D11),"") -> 0 | F11: =IFERROR(IF($C11="",$D11,(E11*F$4)+E11),"") -> 0 | G11: =IFERROR(IF($C11="",$D11,(F11*G$4)+F11),"") -> 0 | H11: =IFERROR(IF($C11="",$D11,(G11*H$4)+G11),"") -> 0
B12: Gás | D12: 0 | E12: =IFERROR(IF($C12="",$D12,(D12*E$4)+D12),"") -> 0 | F12: =IFERROR(IF($C12="",$D12,(E12*F$4)+E12),"") -> 0 | G12: =IFERROR(IF($C12="",$D12,(F12*G$4)+F12),"") -> 0 | H12: =IFERROR(IF($C12="",$D12,(G12*H$4)+G12),"") -> 0
B13: Telefone - Celular | D13: 0 | E13: =IFERROR(IF($C13="",$D13,(D13*E$4)+D13),"") -> 0 | F13: =IFERROR(IF($C13="",$D13,(E13*F$4)+E13),"") -> 0 | G13: =IFERROR(IF($C13="",$D13,(F13*G$4)+F13),"") -> 0 | H13: =IFERROR(IF($C13="",$D13,(G13*H$4)+G13),"") -> 0
B14: Internet | D14: 130 | E14: =IFERROR(IF($C14="",$D14,(D14*E$4)+D14),"") -> 130 | F14: =IFERROR(IF($C14="",$D14,(E14*F$4)+E14),"") -> 130 | G14: =IFERROR(IF($C14="",$D14,(F14*G$4)+F14),"") -> 130 | H14: =IFERROR(IF($C14="",$D14,(G14*H$4)+G14),"") -> 130
B15: Serviços Terceirizados
B16: Manutenção Software | D16: 500 | E16: =IFERROR(IF($C16="",$D16,(D16*E$4)+D16),"") -> 500 | F16: =IFERROR(IF($C16="",$D16,(E16*F$4)+E16),"") -> 500 | G16: =IFERROR(IF($C16="",$D16,(F16*G$4)+F16),"") -> 500 | H16: =IFERROR(IF($C16="",$D16,(G16*H$4)+G16),"") -> 500
B17: Seguro Empresarial / Responsabilidade Civil | D17: 0 | E17: =IFERROR(IF($C17="",$D17,(D17*E$4)+D17),"") -> 0 | F17: =IFERROR(IF($C17="",$D17,(E17*F$4)+E17),"") -> 0 | G17: =IFERROR(IF($C17="",$D17,(F17*G$4)+F17),"") -> 0 | H17: =IFERROR(IF($C17="",$D17,(G17*H$4)+G17),"") -> 0
B18: Manutenção Instalação Física | D18: 0 | E18: =IFERROR(IF($C18="",$D18,(D18*E$4)+D18),"") -> 0 | F18: =IFERROR(IF($C18="",$D18,(E18*F$4)+E18),"") -> 0 | G18: =IFERROR(IF($C18="",$D18,(F18*G$4)+F18),"") -> 0 | H18: =IFERROR(IF($C18="",$D18,(G18*H$4)+G18),"") -> 0
B19: Manutenção Equipamentos Diversos | D19: 0 | E19: =IFERROR(IF($C19="",$D19,(D19*E$4)+D19),"") -> 0 | F19: =IFERROR(IF($C19="",$D19,(E19*F$4)+E19),"") -> 0 | G19: =IFERROR(IF($C19="",$D19,(F19*G$4)+F19),"") -> 0 | H19: =IFERROR(IF($C19="",$D19,(G19*H$4)+G19),"") -> 0
B20: Contador | D20: 700 | E20: =IFERROR(IF($C20="",$D20,(D20*E$4)+D20),"") -> 700 | F20: =IFERROR(IF($C20="",$D20,(E20*F$4)+E20),"") -> 700 | G20: =IFERROR(IF($C20="",$D20,(F20*G$4)+F20),"") -> 700 | H20: =IFERROR(IF($C20="",$D20,(G20*H$4)+G20),"") -> 700
B21: Auditoria de Vigilância Sanitária | D21: 0 | E21: =IFERROR(IF($C21="",$D21,(D21*E$4)+D21),"") -> 0 | F21: =IFERROR(IF($C21="",$D21,(E21*F$4)+E21),"") -> 0 | G21: =IFERROR(IF($C21="",$D21,(F21*G$4)+F21),"") -> 0 | H21: =IFERROR(IF($C21="",$D21,(G21*H$4)+G21),"") -> 0
B22: Serviços de Segurança/Monitoramento | D22: 0 | E22: =IFERROR(IF($C22="",$D22,(D22*E$4)+D22),"") -> 0 | F22: =IFERROR(IF($C22="",$D22,(E22*F$4)+E22),"") -> 0 | G22: =IFERROR(IF($C22="",$D22,(F22*G$4)+F22),"") -> 0 | H22: =IFERROR(IF($C22="",$D22,(G22*H$4)+G22),"") -> 0
B23: Despesas bancárias | D23: 90 | E23: =IFERROR(IF($C23="",$D23,(D23*E$4)+D23),"") -> 90 | F23: =IFERROR(IF($C23="",$D23,(E23*F$4)+E23),"") -> 90 | G23: =IFERROR(IF($C23="",$D23,(F23*G$4)+F23),"") -> 90 | H23: =IFERROR(IF($C23="",$D23,(G23*H$4)+G23),"") -> 90
B24: Serviços Gerais
B25: Correios | D25: 0 | E25: =IFERROR(IF($C25="",$D25,(D25*E$4)+D25),"") -> 0 | F25: =IFERROR(IF($C25="",$D25,(E25*F$4)+E25),"") -> 0 | G25: =IFERROR(IF($C25="",$D25,(F25*G$4)+F25),"") -> 0 | H25: =IFERROR(IF($C25="",$D25,(G25*H$4)+G25),"") -> 0
B26: Moto-Boy | D26: 0 | E26: =IFERROR(IF($C26="",$D26,(D26*E$4)+D26),"") -> 0 | F26: =IFERROR(IF($C26="",$D26,(E26*F$4)+E26),"") -> 0 | G26: =IFERROR(IF($C26="",$D26,(F26*G$4)+F26),"") -> 0 | H26: =IFERROR(IF($C26="",$D26,(G26*H$4)+G26),"") -> 0
B27: Faxina | D27: 0 | E27: =IFERROR(IF($C27="",$D27,(D27*E$4)+D27),"") -> 0 | F27: =IFERROR(IF($C27="",$D27,(E27*F$4)+E27),"") -> 0 | G27: =IFERROR(IF($C27="",$D27,(F27*G$4)+F27),"") -> 0 | H27: =IFERROR(IF($C27="",$D27,(G27*H$4)+G27),"") -> 0
B28: Materiais Diversos
B29: Material de Trabalho | D29: 0 | E29: =IFERROR(IF($C29="",$D29,(D29*E$4)+D29),"") -> 0 | F29: =IFERROR(IF($C29="",$D29,(E29*F$4)+E29),"") -> 0 | G29: =IFERROR(IF($C29="",$D29,(F29*G$4)+F29),"") -> 0 | H29: =IFERROR(IF($C29="",$D29,(G29*H$4)+G29),"") -> 0
B30: Materiais de Limpeza | D30: 0 | E30: =IFERROR(IF($C30="",$D30,(D30*E$4)+D30),"") -> 0 | F30: =IFERROR(IF($C30="",$D30,(E30*F$4)+E30),"") -> 0 | G30: =IFERROR(IF($C30="",$D30,(F30*G$4)+F30),"") -> 0 | H30: =IFERROR(IF($C30="",$D30,(G30*H$4)+G30),"") -> 0
B31: Materiais de Escritório | D31: 50 | E31: =IFERROR(IF($C31="",$D31,(D31*E$4)+D31),"") -> 50 | F31: =IFERROR(IF($C31="",$D31,(E31*F$4)+E31),"") -> 50 | G31: =IFERROR(IF($C31="",$D31,(F31*G$4)+F31),"") -> 50 | H31: =IFERROR(IF($C31="",$D31,(G31*H$4)+G31),"") -> 50
B32: Outros - diretamente na empresa
B33: Provisão Visita de Desenvolvimento do Franqueado | D33: 204.17 | E33: =((((12/Premissas!W70)*Premissas!H63)/12)) -> 204.16667 | F33: =((((12/Premissas!W70)*Premissas!I63)/12)) -> 204.16667 | G33: =((((12/Premissas!W70)*Premissas!J63)/12)) -> 204.16667 | H33: =((((12/Premissas!W70)*Premissas!K63)/12)) -> 204.16667
B34: Lanches e Refeições | D34: 0 | E34: =IFERROR(IF($C34="",$D34,(D34*E$4)+D34),"") -> 0 | F34: =IFERROR(IF($C34="",$D34,(E34*F$4)+E34),"") -> 0 | G34: =IFERROR(IF($C34="",$D34,(F34*G$4)+F34),"") -> 0 | H34: =IFERROR(IF($C34="",$D34,(G34*H$4)+G34),"") -> 0
B35: Combustível - considerar um custo por km rodado mínimo de R$1,10 | D35: 500 | E35: =IFERROR(IF($C35="",$D35,(D35*E$4)+D35),"") -> 500 | F35: =IFERROR(IF($C35="",$D35,(E35*F$4)+E35),"") -> 500 | G35: =IFERROR(IF($C35="",$D35,(F35*G$4)+F35),"") -> 500 | H35: =IFERROR(IF($C35="",$D35,(G35*H$4)+G35),"") -> 500
B36: Treinamento | D36: 0 | E36: =IFERROR(IF($C36="",$D36,(D36*E$4)+D36),"") -> 0 | F36: =IFERROR(IF($C36="",$D36,(E36*F$4)+E36),"") -> 0 | G36: =IFERROR(IF($C36="",$D36,(F36*G$4)+F36),"") -> 0 | H36: =IFERROR(IF($C36="",$D36,(G36*H$4)+G36),"") -> 0
B37: Sala de Coworking | D37: 500 | E37: =IFERROR(IF($C37="",$D37,(D37*E$4)+D37),"") -> 500 | F37: =IFERROR(IF($C37="",$D37,(E37*F$4)+E37),"") -> 500 | G37: =IFERROR(IF($C37="",$D37,(F37*G$4)+F37),"") -> 500 | H37: =IFERROR(IF($C37="",$D37,(G37*H$4)+G37),"") -> 500
B38: Freelancer | D38: 0 | E38: =IFERROR(IF($C38="",$D38,(D38*E$4)+D38),"") -> 0 | F38: =IFERROR(IF($C38="",$D38,(E38*F$4)+E38),"") -> 0 | G38: =IFERROR(IF($C38="",$D38,(F38*G$4)+F38),"") -> 0 | H38: 0
B39: E-cad | D39: 0 | E39: =IFERROR(IF($C39="",$D39,(D39*E$4)+D39),"") -> 0 | F39: =IFERROR(IF($C39="",$D39,(E39*F$4)+E39),"") -> 0 | G39: =IFERROR(IF($C39="",$D39,(F39*G$4)+F39),"") -> 0 | H39: =IFERROR(IF($C39="",$D39,(G39*H$4)+G39),"") -> 0
B40: Provisionamento para gastos não previstos | D40: 200 | E40: =IFERROR(IF($C40="",$D40,(D40*E$4)+D40),"") -> 200 | F40: =IFERROR(IF($C40="",$D40,(E40*F$4)+E40),"") -> 200 | G40: =IFERROR(IF($C40="",$D40,(F40*G$4)+F40),"") -> 200 | H40: =IFERROR(IF($C40="",$D40,(G40*H$4)+G40),"") -> 200
...

Sheet Recursos Humanos
B2: SIMULAÇÃO DE SALÁRIOS E ENCARGOS SOCIAIS MENSAIS | N2: =IF(OR(DRE!$C$26="",DRE!$C$26=0%),"","*")
H3: Total de dias trabalhados por mês: | N3: 26
B4: Descrição | C4: Qtde | D4: Remuneração Unitária | E4: Salários | F4: Encargos Trabalhistas | G4: Encargos Comissão | H4: Vale Transporte - Base | I4: Vale Alimentação | J4: Kit Uniforme Básico | K4: Seguro de Vida | L4: Comissão (%) | M4: Tem Comissão (*) | N4: TOTAL
E5: 0 | F5: 0 | G5: 0 | J5: 13.33
F6: uni | G6: uni | H6: =H5*N3*2 -> 0 | I6: =$I$5*$N$3 -> 0 | J6: =J5/12 -> 1.1108333
B7: Franqueado (Pró-Labore) (*) | C7: 1 | D7: 0 | E7: =C7*D7 -> 0 | F7: =D7*0.11 -> 0 | K7: =$K$5*C7 -> 0 | N7: =IF(B7="","",SUM(E7:F7,H7:K7)) -> 0 | P7: Salário Base | R7: 1000 | S7: Quantidade | T7: 1
B8: Atendente | C8: =Receitas_1!Q204 -> 2 | D8: 2000 | E8: =C8*D8 -> 4000 | F8: =C8*(((D8/12)+(D8/12)+((D8/12)/3)+(D8*0.08)+(D8*0)+(((D8/12)+(D8/12))*0.0933))+((D8*0.08)*0.4))*1.2 -> 1545.5733 | G8: =IFERROR(IF(OR(D8=0,D8=""),"",IF(M8<>"*","",(F8/E8))),"") | H8: =$H$6*C8 -> 0 | I8: =$I$6*C8 -> 0 | J8: =$J$6*C8 -> 2.2216667 | K8: =$K$5*C8 -> 0 | L8: =IF(D8="","",IF(M8="","n/a",DRE!$C$26)) -> n/a | N8: =IF(B8="","",SUM(E8:F8,H8:K8)) -> 5547.795 | P8: DESCRIÇÃO | R8: VALORES
D9: 0 | E9: =C9*D9 -> 0 | F9: =C9*(((D9/12)+(D9/12)+((D9/12)/3)+(D9*0.08)+(D9*0)+(((D9/12)+(D9/12))*0.0933))+((D9*0.08)*0.4))*1.2 -> 0 | G9: =IFERROR(IF(OR(D9=0,D9=""),"",IF(M9<>"*","",(F9/E9))),"") | H9: =$H$6*C9 -> 0 | I9: =$I$6*C9 -> 0 | J9: =$J$6*C9 -> 0 | K9: 0 | L9: =IF(D9="","",IF(M9="","n/a",DRE!$C$26)) -> n/a | N9: =IF(B9="","",SUM(E9:F9,H9:K9)) | P9: Salário Base | R9: =R7 -> 1000 | S9: =R9*$T$7 -> 1000 | U9: =S9 -> 1000
D10: 0 | E10: =C10*D10 -> 0 | F10: =C10*(((D10/12)+(D10/12)+((D10/12)/3)+(D10*0.08)+(D10*0)+(((D10/12)+(D10/12))*0.0933))+((D10*0.08)*0.4))*1.2 -> 0 | G10: =IFERROR(IF(OR(D10=0,D10=""),"",IF(M10<>"*","",(F10/E10))),"") | H10: =$H$6*C10 -> 0 | I10: =$I$6*C10 -> 0 | J10: 0 | K10: 0 | L10: =IF(D10="","",IF(M10="","n/a",DRE!$C$26)) -> n/a | N10: =IF(B10="","",SUM(E10:F10,H10:K10))
D11: 0 | E11: =C11*D11 -> 0 | F11: =C11*(((D11/12)+(D11/12)+((D11/12)/3)+(D11*0.08)+(D11*0)+(((D11/12)+(D11/12))*0.0933))+((D11*0.08)*0.4))*1.2 -> 0 | G11: =IFERROR(IF(OR(D11=0,D11=""),"",IF(M11<>"*","",(F11/E11))),"") | H11: =$H$6*C11 -> 0 | I11: =$I$6*C11 -> 0 | J11: 0 | K11: 0 | L11: =IF(D11="","",IF(M11="","n/a",DRE!$C$26)) -> n/a | N11: =IF(B11="","",SUM(E11:F11,H11:K11))
D12: 0 | E12: =C12*D12 -> 0 | F12: =C12*(((D12/12)+(D12/12)+((D12/12)/3)+(D12*0.08)+(D12*0)+(((D12/12)+(D12/12))*0.0933))+((D12*0.08)*0.4))*1.2 -> 0 | G12: =IFERROR(IF(OR(D12=0,D12=""),"",IF(M12<>"*","",(F12/E12))),"") | H12: =$H$6*C12 -> 0 | I12: =$I$6*C12 -> 0 | J12: =$J$6*C12 -> 0 | K12: =$K$5*C12 -> 0 | L12: =IF(D12="","",IF(M12="","n/a",DRE!$C$26)) -> n/a | N12: =IF(B12="","",SUM(E12:F12,H12:K12)) | P12: Férias 1/12 avos | R12: =R9/12 -> 83.333333 | S12: =R12*$T$7 -> 83.333333
D13: 0 | E13: =C13*D13 -> 0 | F13: =C13*(((D13/12)+(D13/12)+((D13/12)/3)+(D13*0.08)+(D13*0)+(((D13/12)+(D13/12))*0.0933))+((D13*0.08)*0.4))*1.2 -> 0 | G13: =IFERROR(IF(OR(D13=0,D13=""),"",IF(M13<>"*","",(F13/E13))),"") | H13: =$H$6*C13 -> 0 | I13: =$I$6*C13 -> 0 | J13: =$J$6*C13 -> 0 | K13: =$K$5*C13 -> 0 | L13: =IF(D13="","",IF(M13="","n/a",DRE!$C$26)) -> n/a | N13: =IF(B13="","",SUM(E13:F13,H13:K13)) | P13: 13º Salário 1/12 avos | R13: =R9/12 -> 83.333333 | S13: =R13*$T$7 -> 83.333333
B14: TOTAL MENSAL (Ano 1) | C14: =SUM(C7:C13) -> 3 | E14: =SUM(E7:E13) -> 4000 | F14: =SUM(F7:F13) -> 1545.5733 | G14: =IFERROR(IF(OR(DRE!$C$26=0%,DRE!$C$26=""),"",F14/E14),"") | H14: =SUM(H7:H13) -> 0 | I14: =SUM(I7:I13) -> 0 | J14: =SUM(J7:J13) -> 2.2216667 | K14: =SUM(K7:K13) -> 0 | N14: =SUM(N7:N13) -> 5547.795 | P14: 1/3 sobre Férias | R14: =R12/3 -> 27.777778 | S14: =R14*$T$7 -> 27.777778
P15: FGTS | Q15: 0.08 | R15: =R7*Q15 -> 80 | S15: =R15*$T$7 -> 80
P16: INSS(Contribuição Mínima) | Q16: 0 | R16: =R7*Q16 -> 0 | S16: =R16*$T$7 -> 0
B17: =B7 -> Franqueado (Pró-Labore) (*) | C17: 1 | E17: =C17*D17 -> 0 | F17: =D17*0.11 -> 0 | K17: =$K$5*C17 -> 0 | N17: =IF(B17="","",SUM(E17:F17,H17:K17)) -> 0 | P17: Provisão FGTS (13º e Férias) | Q17: 0.093337493 | R17: =(R13+R12)*Q17 -> 15.556249 | S17: =R17*$T$7 -> 15.556249
B18: =B8 -> Atendente | C18: =Receitas_1!AC204 -> 2 | D18: 2000 | E18: =C18*D18 -> 4000 | F18: =C18*(((D18/12)+(D18/12)+((D18/12)/3)+(D18*0.08)+(D18*0)+(((D18/12)+(D18/12))*0.0933))+((D18*0.08)*0.4))*1.2 -> 1545.5733 | G18: =IFERROR(IF(OR(D18=0,D18=""),"",IF(M18<>"*","",(F18/E18))),"") | H18: =$H$6*C18 -> 0 | I18: =$I$6*C18 -> 0 | J18: =$J$6*C18 -> 2.2216667 | K18: =$K$5*C18 -> 0 | L18: =IF(D18="","",IF(M18="","n/a",DRE!$C$26)) -> n/a | N18: =IF(B18="","",SUM(E18:F18,H18:K18)) -> 5547.795 | P18: Provisão INSS (13º e Férias) | Q18: 0 | R18: =(R16+R12)*Q18 -> 0 | S18: =R18*$T$7 -> 0 | U18: =SUM(S12:T18) -> 290.00069
E19: =C19*D19 -> 0 | F19: =C19*(((D19/12)+(D19/12)+((D19/12)/3)+(D19*0.08)+(D19*0)+(((D19/12)+(D19/12))*0.0933))+((D19*0.08)*0.4))*1.2 -> 0 | G19: =IFERROR(IF(OR(D19=0,D19=""),"",IF(M19<>"*","",(F19/E19))),"") | H19: =$H$6*C19 -> 0 | I19: =$I$6*C19 -> 0 | J19: =$J$6*C19 -> 0 | K19: =$K$5*C19 -> 0 | L19: =IF(D19="","",IF(M19="","n/a",DRE!$C$26)) | N19: =IF(B19="","",SUM(E19:F19,H19:K19))
E20: =C20*D20 -> 0 | F20: =C20*(((D20/12)+(D20/12)+((D20/12)/3)+(D20*0.08)+(D20*0)+(((D20/12)+(D20/12))*0.0933))+((D20*0.08)*0.4))*1.2 -> 0 | G20: =IFERROR(IF(OR(D20=0,D20=""),"",IF(M20<>"*","",(F20/E20))),"") | H20: =$H$6*C20 -> 0 | I20: =$I$6*C20 -> 0 | J20: =$J$6*C20 -> 0 | K20: =$K$5*C20 -> 0 | L20: =IF(D20="","",IF(M20="","n/a",DRE!$C$26)) | N20: =IF(B20="","",SUM(E20:F20,H20:K20))
E21: =C21*D21 -> 0 | F21: =C21*(((D21/12)+(D21/12)+((D21/12)/3)+(D21*0.08)+(D21*0)+(((D21/12)+(D21/12))*0.0933))+((D21*0.08)*0.4))*1.2 -> 0 | G21: =IFERROR(IF(OR(D21=0,D21=""),"",IF(M21<>"*","",(F21/E21))),"") | H21: =$H$6*C21 -> 0 | I21: =$I$6*C21 -> 0 | J21: =$J$6*C21 -> 0 | K21: =$K$5*C21 -> 0 | L21: =IF(D21="","",IF(M21="","n/a",DRE!$C$26)) | N21: =IF(B21="","",SUM(E21:F21,H21:K21))
E22: =C22*D22 -> 0 | F22: =C22*(((D22/12)+(D22/12)+((D22/12)/3)+(D22*0.08)+(D22*0)+(((D22/12)+(D22/12))*0.0933))+((D22*0.08)*0.4))*1.2 -> 0 | G22: =IFERROR(IF(OR(D22=0,D22=""),"",IF(M22<>"*","",(F22/E22))),"") | H22: =$H$6*C22 -> 0 | I22: =$I$6*C22 -> 0 | J22: =$J$6*C22 -> 0 | K22: =$K$5*C22 -> 0 | L22: =IF(D22="","",IF(M22="","n/a",DRE!$C$26)) | N22: =IF(B22="","",SUM(E22:F22,H22:K22))
E23: =C23*D23 -> 0 | F23: =C23*(((D23/12)+(D23/12)+((D23/12)/3)+(D23*0.08)+(D23*0)+(((D23/12)+(D23/12))*0.0933))+((D23*0.08)*0.4))*1.2 -> 0 | G23: =IFERROR(IF(OR(D23=0,D23=""),"",IF(M23<>"*","",(F23/E23))),"") | H23: =$H$6*C23 -> 0 | I23: =$I$6*C23 -> 0 | J23: =$J$6*C23 -> 0 | K23: =$K$5*C23 -> 0 | L23: =IF(D23="","",IF(M23="","n/a",DRE!$C$26)) | N23: =IF(B23="","",SUM(E23:F23,H23:K23)) | P23: Desconto Vale Transporte | R23: =-(#REF!-#REF!) -> #REF! | S23: =R23*$T$7 -> #REF! | U23: =S23 -> #REF!
B24: TOTAL MENSAL (Ano 2) | C24: =SUM(C17:C23) -> 3 | E24: =SUM(E17:E23) -> 4000 | F24: =SUM(F17:F23) -> 1545.5733 | G24: =IFERROR(IF(OR(DRE!$C$26=0%,DRE!$C$26=""),"",F24/E24),"") | H24: =SUM(H17:H23) -> 0 | I24: =SUM(I17:I23) -> 0 | J24: =SUM(J17:J23) -> 2.2216667 | K24: =SUM(K17:K23) -> 0 | N24: =SUM(N17:N23) -> 5547.795 | P24: Vale Alimentação | R24: =I6 -> 0 | S24: =R24*$T$7 -> 0 | U24: =S24 -> 0
P25: Kit Uniforme Básico | R25: =J6 -> 1.1108333 | S25: =R25*$T$7 -> 1.1108333 | U25: =S25 -> 1.1108333
P26: Plano de Saúde | R26: =K5 -> 0 | S26: =R26*$T$7 -> 0 | U26: =S26 -> 0
B27: =B7 -> Franqueado (Pró-Labore) (*) | C27: 1 | E27: =C27*D27 -> 0 | F27: =D27*0.11 -> 0 | K27: =$K$5*C27 -> 0 | N27: =IF(B27="","",SUM(E27:F27,H27:K27)) -> 0 | P27: Gratificações e Comissões | S27: =R27*$T$7 -> 0 | U27: =S27 -> 0
B28: =B8 -> Atendente | C28: =Receitas_1!AO204 -> 2 | D28: 2000 | E28: =C28*D28 -> 4000 | F28: =C28*(((D28/12)+(D28/12)+((D28/12)/3)+(D28*0.08)+(D28*0)+(((D28/12)+(D28/12))*0.0933))+((D28*0.08)*0.4))*1.2 -> 1545.5733 | G28: =IFERROR(IF(OR(D28=0,D28=""),"",IF(M28<>"*","",(F28/E28))),"") | H28: =$H$6*C28 -> 0 | I28: =$I$6*C28 -> 0 | J28: =$J$6*C28 -> 2.2216667 | K28: =$K$5*C28 -> 0 | L28: =IF(D28="","",IF(M28="","n/a",DRE!$C$26)) -> n/a | N28: =IF(B28="","",SUM(E28:F28,H28:K28)) -> 5547.795 | P28: TOTAL | R28: =SUM(R9:R22)+R23+R24+R25+R26+R27 -> #REF! | S28: =SUM(S9:T22)+S23+S24+S25+S26+S27 -> #REF! | U28: =SUM(U9+U18+#REF!+U24+U25+U26+U27) -> #REF!
E29: =C29*D29 -> 0 | F29: =C29*(((D29/12)+(D29/12)+((D29/12)/3)+(D29*0.08)+(D29*0)+(((D29/12)+(D29/12))*0.0933))+((D29*0.08)*0.4))*1.2 -> 0 | G29: =IFERROR(IF(OR(D29=0,D29=""),"",IF(M29<>"*","",(F29/E29))),"") | H29: =$H$6*C29 -> 0 | I29: =$I$6*C29 -> 0 | J29: =$J$6*C29 -> 0 | K29: =$K$5*C29 -> 0 | L29: =IF(D29="","",IF(M29="","n/a",DRE!$C$26)) | N29: =IF(B29="","",SUM(E29:F29,H29:K29))
E30: =C30*D30 -> 0 | F30: =C30*(((D30/12)+(D30/12)+((D30/12)/3)+(D30*0.08)+(D30*0)+(((D30/12)+(D30/12))*0.0933))+((D30*0.08)*0.4))*1.2 -> 0 | G30: =IFERROR(IF(OR(D30=0,D30=""),"",IF(M30<>"*","",(F30/E30))),"") | H30: =$H$6*C30 -> 0 | I30: =$I$6*C30 -> 0 | J30: =$J$6*C30 -> 0 | K30: =$K$5*C30 -> 0 | L30: =IF(D30="","",IF(M30="","n/a",DRE!$C$26)) | N30: =IF(B30="","",SUM(E30:F30,H30:K30))
E31: =C31*D31 -> 0 | F31: =C31*(((D31/12)+(D31/12)+((D31/12)/3)+(D31*0.08)+(D31*0)+(((D31/12)+(D31/12))*0.0933))+((D31*0.08)*0.4))*1.2 -> 0 | G31: =IFERROR(IF(OR(D31=0,D31=""),"",IF(M31<>"*","",(F31/E31))),"") | H31: =$H$6*C31 -> 0 | I31: =$I$6*C31 -> 0 | J31: =$J$6*C31 -> 0 | K31: =$K$5*C31 -> 0 | L31: =IF(D31="","",IF(M31="","n/a",DRE!$C$26)) | N31: =IF(B31="","",SUM(E31:F31,H31:K31))
E32: =C32*D32 -> 0 | F32: =C32*(((D32/12)+(D32/12)+((D32/12)/3)+(D32*0.08)+(D32*0)+(((D32/12)+(D32/12))*0.0933))+((D32*0.08)*0.4))*1.2 -> 0 | G32: =IFERROR(IF(OR(D32=0,D32=""),"",IF(M32<>"*","",(F32/E32))),"") | H32: =$H$6*C32 -> 0 | I32: =$I$6*C32 -> 0 | J32: =$J$6*C32 -> 0 | K32: =$K$5*C32 -> 0 | L32: =IF(D32="","",IF(M32="","n/a",DRE!$C$26)) | N32: =IF(B32="","",SUM(E32:F32,H32:K32))
E33: =C33*D33 -> 0 | F33: =C33*(((D33/12)+(D33/12)+((D33/12)/3)+(D33*0.08)+(D33*0)+(((D33/12)+(D33/12))*0.0933))+((D33*0.08)*0.4))*1.2 -> 0 | G33: =IFERROR(IF(OR(D33=0,D33=""),"",IF(M33<>"*","",(F33/E33))),"") | H33: =$H$6*C33 -> 0 | I33: =$I$6*C33 -> 0 | J33: =$J$6*C33 -> 0 | K33: =$K$5*C33 -> 0 | L33: =IF(D33="","",IF(M33="","n/a",DRE!$C$26)) | N33: =IF(B33="","",SUM(E33:F33,H33:K33))
B34: TOTAL MENSAL (Ano 3) | C34: =SUM(C27:C33) -> 3 | E34: =SUM(E27:E33) -> 4000 | F34: =SUM(F27:F33) -> 1545.5733 | G34: =IFERROR(IF(OR(DRE!$C$26=0%,DRE!$C$26=""),"",F34/E34),"") | H34: =SUM(H27:H33) -> 0 | I34: =SUM(I27:I33) -> 0 | J34: =SUM(J27:J33) -> 2.2216667 | K34: =SUM(K27:K33) -> 0 | N34: =SUM(N27:N33) -> 5547.795
B37: =B7 -> Franqueado (Pró-Labore) (*) | C37: 1 | E37: =C37*D37 -> 0 | F37: =D37*0.11 -> 0 | K37: =$K$5*C37 -> 0 | N37: =IF(B37="","",SUM(E37:F37,H37:K37)) -> 0
B38: =B8 -> Atendente | C38: =Receitas_1!BA204 -> 2 | D38: 2000 | E38: =C38*D38 -> 4000 | F38: =C38*(((D38/12)+(D38/12)+((D38/12)/3)+(D38*0.08)+(D38*0)+(((D38/12)+(D38/12))*0.0933))+((D38*0.08)*0.4))*1.2 -> 1545.5733 | G38: =IFERROR(IF(OR(D38=0,D38=""),"",IF(M38<>"*","",(F38/E38))),"") | H38: =$H$6*C38 -> 0 | I38: =$I$6*C38 -> 0 | J38: =$J$6*C38 -> 2.2216667 | K38: =$K$5*C38 -> 0 | L38: =IF(D38="","",IF(M38="","n/a",DRE!$C$26)) -> n/a | N38: =IF(B38="","",SUM(E38:F38,H38:K38)) -> 5547.795
E39: =C39*D39 -> 0 | F39: =C39*(((D39/12)+(D39/12)+((D39/12)/3)+(D39*0.08)+(D39*0)+(((D39/12)+(D39/12))*0.0933))+((D39*0.08)*0.4))*1.2 -> 0 | G39: =IFERROR(IF(OR(D39=0,D39=""),"",IF(M39<>"*","",(F39/E39))),"") | H39: =$H$6*C39 -> 0 | I39: =$I$6*C39 -> 0 | J39: =$J$6*C39 -> 0 | K39: =$K$5*C39 -> 0 | L39: =IF(D39="","",IF(M39="","n/a",DRE!$C$26)) | N39: =IF(B39="","",SUM(E39:F39,H39:K39))
E40: =C40*D40 -> 0 | F40: =C40*(((D40/12)+(D40/12)+((D40/12)/3)+(D40*0.08)+(D40*0)+(((D40/12)+(D40/12))*0.0933))+((D40*0.08)*0.4))*1.2 -> 0 | G40: =IFERROR(IF(OR(D40=0,D40=""),"",IF(M40<>"*","",(F40/E40))),"") | H40: =$H$6*C40 -> 0 | I40: =$I$6*C40 -> 0 | J40: =$J$6*C40 -> 0 | K40: =$K$5*C40 -> 0 | L40: =IF(D40="","",IF(M40="","n/a",DRE!$C$26)) | N40: =IF(B40="","",SUM(E40:F40,H40:K40))
E41: =C41*D41 -> 0 | F41: =C41*(((D41/12)+(D41/12)+((D41/12)/3)+(D41*0.08)+(D41*0)+(((D41/12)+(D41/12))*0.0933))+((D41*0.08)*0.4))*1.2 -> 0 | G41: =IFERROR(IF(OR(D41=0,D41=""),"",IF(M41<>"*","",(F41/E41))),"") | H41: =$H$6*C41 -> 0 | I41: =$I$6*C41 -> 0 | J41: =$J$6*C41 -> 0 | K41: =$K$5*C41 -> 0 | L41: =IF(D41="","",IF(M41="","n/a",DRE!$C$26)) | N41: =IF(B41="","",SUM(E41:F41,H41:K41))
E42: =C42*D42 -> 0 | F42: =C42*(((D42/12)+(D42/12)+((D42/12)/3)+(D42*0.08)+(D42*0)+(((D42/12)+(D42/12))*0.0933))+((D42*0.08)*0.4))*1.2 -> 0 | G42: =IFERROR(IF(OR(D42=0,D42=""),"",IF(M42<>"*","",(F42/E42))),"") | H42: =$H$6*C42 -> 0 | I42: =$I$6*C42 -> 0 | J42: =$J$6*C42 -> 0 | K42: =$K$5*C42 -> 0 | L42: =IF(D42="","",IF(M42="","n/a",DRE!$C$26)) | N42: =IF(B42="","",SUM(E42:F42,H42:K42))
E43: =C43*D43 -> 0 | F43: =C43*(((D43/12)+(D43/12)+((D43/12)/3)+(D43*0.08)+(D43*0)+(((D43/12)+(D43/12))*0.0933))+((D43*0.08)*0.4))*1.2 -> 0 | G43: =IFERROR(IF(OR(D43=0,D43=""),"",IF(M43<>"*","",(F43/E43))),"") | H43: =$H$6*C43 -> 0 | I43: =$I$6*C43 -> 0 | J43: =$J$6*C43 -> 0 | K43: =$K$5*C43 -> 0 | L43: =IF(D43="","",IF(M43="","n/a",DRE!$C$26)) | N43: =IF(B43="","",SUM(E43:F43,H43:K43))
...

Sheet Receitas_1
C1: SIMULAÇÃO DE FORMAÇÃO DA RECEITA
F2: Ano 1 | G2: Ano 1 | H2: Ano 1 | I2: Ano 1 | J2: Ano 1 | K2: Ano 1 | L2: Ano 1 | M2: Ano 1 | N2: Ano 1 | O2: Ano 1 | P2: Ano 1 | Q2: Ano 1 | R2: Ano 2 | S2: Ano 2 | T2: Ano 2 | U2: Ano 2 | V2: Ano 2 | W2: Ano 2 | X2: Ano 2 | Y2: Ano 2 | Z2: Ano 2 | AA2: Ano 2 | AB2: Ano 2 | AC2: Ano 2 | AD2: Ano 3 | AE2: Ano 3 | AF2: Ano 3 | AG2: Ano 3 | AH2: Ano 3 | AI2: Ano 3 | AJ2: Ano 3 | AK2: Ano 3 | AL2: Ano 3 | AM2: Ano 3 | AN2: Ano 3 | AO2: Ano 3 | AP2: Ano 4 | AQ2: Ano 4 | AR2: Ano 4 | AS2: Ano 4 | AT2: Ano 4 | AU2: Ano 4 | AV2: Ano 4 | AW2: Ano 4 | AX2: Ano 4 | AY2: Ano 4 | AZ2: Ano 4 | BA2: Ano 4 | BB2: Ano 5 | BC2: Ano 5 | BD2: Ano 5 | BE2: Ano 5 | BF2: Ano 5 | BG2: Ano 5 | BH2: Ano 5 | BI2: Ano 5 | BJ2: Ano 5 | BK2: Ano 5 | BL2: Ano 5 | BM2: Ano 5 | BO2: Ano 1 | BP2: Ano 2 | BQ2: Ano 3 | BR2: Ano 4 | BS2: Ano 5
D3: Cenário | E3: Conservador | F3: Jan | G3: Fev | H3: Mar | I3: Abr | J3: Mai | K3: Jun | L3: Jul | M3: Ago | N3: Set | O3: Out | P3: Nov | Q3: Dez | R3: Jan | S3: Fev | T3: Mar | U3: Abr | V3: Mai | W3: Jun | X3: Jul | Y3: Ago | Z3: Set | AA3: Out | AB3: Nov | AC3: Dez | AD3: Jan | AE3: Fev | AF3: Mar | AG3: Abr | AH3: Mai | AI3: Jun | AJ3: Jul | AK3: Ago | AL3: Set | AM3: Out | AN3: Nov | AO3: Dez | AP3: Jan | AQ3: Fev | AR3: Mar | AS3: Abr | AT3: Mai | AU3: Jun | AV3: Jul | AW3: Ago | AX3: Set | AY3: Out | AZ3: Nov | BA3: Dez | BB3: Jan | BC3: Fev | BD3: Mar | BE3: Abr | BF3: Mai | BG3: Jun | BH3: Jul | BI3: Ago | BJ3: Set | BK3: Out | BL3: Nov | BM3: Dez
B4: Quantidades vendidas | C4: Representatividade nas Vendas em % nos 5 anos | D4: Potencial TOTAL | E4: Quantidade Média Vendida | F4: IMPLANTAÇÃO | G4: Crescimento vs. Mês Anterior => | H4: 1 | I4: 0.5 | J4: 0.33 | K4: 0.25 | L4: 0.2 | M4: 0.16 | N4: 0.14 | O4: 0.13 | P4: 0.11 | Q4: 0.1 | R4: -0.25 | S4: -0.05 | T4: 0.1 | U4: 0.1 | V4: 0.1 | W4: 0.1 | X4: -0.05 | Y4: -0.05 | Z4: 0.07 | AA4: 0.07 | AB4: 0.07 | AC4: 0.1 | AD4: -0.15 | AE4: -0.05 | AF4: 0.05 | AG4: 0.05 | AH4: 0.05 | AI4: 0.07 | AJ4: -0.1 | AK4: -0.1 | AL4: 0.07 | AM4: 0.07 | AN4: 0.07 | AO4: 0.08 | AP4: -0.14 | AQ4: -0.05 | AR4: 0.05 | AS4: 0.05 | AT4: 0.05 | AU4: 0.07 | AV4: -0.1 | AW4: -0.1 | AX4: 0.07 | AY4: 0.07 | AZ4: 0.07 | BA4: 0.08 | BB4: -0.13 | BC4: -0.05 | BD4: 0.05 | BE4: 0.05 | BF4: 0.05 | BG4: 0.07 | BH4: -0.1 | BI4: -0.1 | BJ4: 0.07 | BK4: 0.07 | BL4: 0.07 | BM4: 0.08 | BN4: 0.05 | BO4: 0.05 | BP4: unidades | BQ4: unidades | BR4: unidades | BS4: unidades | BV4: Representatividade nas Vendas em % (Qtde) | BX4: Média Crescimento Ano 1 | BY4: Média Crescimento Ano 2 | BZ4: Média Crescimento Ano 3 | CA4: Média Crescimento Ano 4 | CB4: Média Geral
F5: % de Atingimento => | G5: =IF(E3="Conservador",C162,IF(E3="Moderado",C163,IF(E3="Otimista",C164,C163))) -> 0.054 | H5: =SUM(H6:H50)/SUM($D$6:$D$50) -> 0.108 | I5: =SUM(I6:I50)/SUM($D$6:$D$50) -> 0.162 | J5: =SUM(J6:J50)/SUM($D$6:$D$50) -> 0.21546 | K5: =SUM(K6:K50)/SUM($D$6:$D$50) -> 0.269325 | L5: =SUM(L6:L50)/SUM($D$6:$D$50) -> 0.32319 | M5: =SUM(M6:M50)/SUM($D$6:$D$50) -> 0.3749004 | N5: =SUM(N6:N50)/SUM($D$6:$D$50) -> 0.42738646 | O5: =SUM(O6:O50)/SUM($D$6:$D$50) -> 0.4829467 | ... BM5: =SUM(BM6:BM50)/SUM($D$6:$D$50) -> 0.95412328
B6: Limpeza Residencial - 4 horas | C6: =SUM(F52:BL52)/SUM($F$97:$BM$97) -> 0.46612813 | D6: =F6*'Distribuição de Modelos'!$E$50 -> 418.60405 | E6: 200 | F6: 673 | G6: =IFERROR(IF($D6="","",$G$5*$D6),"") -> 22.604619 | H6: =IFERROR(IF($D6="","",IF(G6+(G6*H$4)>$D6,$D6,G6+(G6*H$4))),"") -> 45.209237 | I6: =IFERROR(IF($D6="","",IF(H6+(H6*I$4)>$D6,$D6,H6+(H6*I$4))),"") -> 67.813856 | J6: =IFERROR(IF($D6="","",IF(I6+(I6*J$4)>$D6,$D6,I6+(I6*J$4))),"") -> 90.192428 | K6: =IFERROR(IF($D6="","",IF(J6+(J6*K$4)>$D6,$D6,J6+(J6*K$4))),"") -> 112.74054 | L6: =IFERROR(IF($D6="","",IF(K6+(K6*L$4)>$D6,$D6,K6+(K6*L$4))),"") -> 135.28864 | M6: =IFERROR(IF($D6="","",IF(L6+(L6*M$4)>$D6,$D6,L6+(L6*M$4))),"") -> 156.93483 | N6: =IFERROR(IF($D6="","",IF(M6+(M6*N$4)>$D6,$D6,M6+(M6*N$4))),"") -> 178.9057 | O6: =IFERROR(IF($D6="","",IF(N6+(N6*O$4)>$D6,$D6,N6+(N6*O$4))),"") -> 202.16344 | ... BM6: =IFERROR(IF($D6="","",IF(BL6+(BL6*BM$4)>$D6,$D6,BL6+(BL6*BM$4))),"") -> 399.39987
B7: Limpeza Empresarial 4 horas | C7: =SUM(F53:BL53)/SUM($F$97:$BM$97) -> 0.13090374 | D7: =F7*'Distribuição de Modelos'!$E$50 -> 117.55745 | E7: 56 | F7: 189 | G7: =IFERROR(IF($D7="","",$G$5*$D7),"") -> 6.3481024 | H7: =IFERROR(IF($D7="","",IF(G7+(G7*H$4)>$D7,$D7,G7+(G7*H$4))),"") -> 12.696205 | I7: =IFERROR(IF($D7="","",IF(H7+(H7*I$4)>$D7,$D7,H7+(H7*I$4))),"") -> 19.044307 | J7: =IFERROR(IF($D7="","",IF(I7+(I7*J$4)>$D7,$D7,I7+(I7*J$4))),"") -> 25.328929 | K7: =IFERROR(IF($D7="","",IF(J7+(J7*K$4)>$D7,$D7,J7+(J7*K$4))),"") -> 31.661161 | L7: =IFERROR(IF($D7="","",IF(K7+(K7*L$4)>$D7,$D7,K7+(K7*L$4))),"") -> 37.993393 | M7: =IFERROR(IF($D7="","",IF(L7+(L7*M$4)>$D7,$D7,L7+(L7*M$4))),"") -> 44.072336 | N7: =IFERROR(IF($D7="","",IF(M7+(M7*N$4)>$D7,$D7,M7+(M7*N$4))),"") -> 50.242463 | O7: =IFERROR(IF($D7="","",IF(N7+(N7*O$4)>$D7,$D7,N7+(N7*O$4))),"") -> 56.773983 | ... BM7: =IFERROR(IF($D7="","",IF(BL7+(BL7*BM$4)>$D7,$D7,BL7+(BL7*BM$4))),"") -> 112.1643
B8: Limpeza condominial 4 horas | C8: =SUM(F54:BL54)/SUM($F$97:$BM$97) -> 0.056101603 | D8: =F8*'Distribuição de Modelos'!$E$50 -> 50.381765 | E8: 24 | F8: 81 | G8: =IFERROR(IF($D8="","",$G$5*$D8),"") -> 2.7206153 | H8: =IFERROR(IF($D8="","",IF(G8+(G8*H$4)>$D8,$D8,G8+(G8*H$4))),"") -> 5.4412306 | I8: =IFERROR(IF($D8="","",IF(H8+(H8*I$4)>$D8,$D8,H8+(H8*I$4))),"") -> 8.161846 | J8: =IFERROR(IF($D8="","",IF(I8+(I8*J$4)>$D8,$D8,I8+(I8*J$4))),"") -> 10.855255 | K8: =IFERROR(IF($D8="","",IF(J8+(J8*K$4)>$D8,$D8,J8+(J8*K$4))),"") -> 13.569069 | L8: =IFERROR(IF($D8="","",IF(K8+(K8*L$4)>$D8,$D8,K8+(K8*L$4))),"") -> 16.282883 | M8: =IFERROR(IF($D8="","",IF(L8+(L8*M$4)>$D8,$D8,L8+(L8*M$4))),"") -> 18.888144 | N8: =IFERROR(IF($D8="","",IF(M8+(M8*N$4)>$D8,$D8,M8+(M8*N$4))),"") -> 21.532484 | O8: =IFERROR(IF($D8="","",IF(N8+(N8*O$4)>$D8,$D8,N8+(N8*O$4))),"") -> 24.331707 | ... BM8: =IFERROR(IF($D8="","",IF(BL8+(BL8*BM$4)>$D8,$D8,BL8+(BL8*BM$4))),"") -> 48.070415
B9: Passadoria - 4 horas | C9: =SUM(F55:BL55)/SUM($F$97:$BM$97) -> 0.055105973 | D9: =F9*'Distribuição de Modelos'!$E$50 -> 41.673806 | E9: 20 | F9: 67 | G9: =IFERROR(IF($D9="","",$G$5*$D9),"") -> 2.2503855 | H9: =IFERROR(IF($D9="","",IF(G9+(G9*H$4)>$D9,$D9,G9+(G9*H$4))),"") -> 4.500771 | I9: =IFERROR(IF($D9="","",IF(H9+(H9*I$4)>$D9,$D9,H9+(H9*I$4))),"") -> 6.7511565 | J9: =IFERROR(IF($D9="","",IF(I9+(I9*J$4)>$D9,$D9,I9+(I9*J$4))),"") -> 8.9790382 | K9: =IFERROR(IF($D9="","",IF(J9+(J9*K$4)>$D9,$D9,J9+(J9*K$4))),"") -> 11.223798 | L9: =IFERROR(IF($D9="","",IF(K9+(K9*L$4)>$D9,$D9,K9+(K9*L$4))),"") -> 13.468557 | M9: =IFERROR(IF($D9="","",IF(L9+(L9*M$4)>$D9,$D9,L9+(L9*M$4))),"") -> 15.623526 | N9: =IFERROR(IF($D9="","",IF(M9+(M9*N$4)>$D9,$D9,M9+(M9*N$4))),"") -> 17.81082 | O9: =IFERROR(IF($D9="","",IF(N9+(N9*O$4)>$D9,$D9,N9+(N9*O$4))),"") -> 20.126227 | ... BM9: =IFERROR(IF($D9="","",IF(BL9+(BL9*BM$4)>$D9,$D9,BL9+(BL9*BM$4))),"") -> 39.761948
B10: Limpeza Residencial - 6 horas | C10: =SUM(F56:BL56)/SUM($F$97:$BM$97) -> 0.049088903 | D10: =F10*'Distribuição de Modelos'!$E$50 -> 33.587843 | E10: 16 | F10: 54 | G10: =IFERROR(IF($D10="","",$G$5*$D10),"") -> 1.8137435 | H10: =IFERROR(IF($D10="","",IF(G10+(G10*H$4)>$D10,$D10,G10+(G10*H$4))),"") -> 3.6274871 | I10: =IFERROR(IF($D10="","",IF(H10+(H10*I$4)>$D10,$D10,H10+(H10*I$4))),"") -> 5.4412306 | J10: =IFERROR(IF($D10="","",IF(I10+(I10*J$4)>$D10,$D10,I10+(I10*J$4))),"") -> 7.2368367 | K10: =IFERROR(IF($D10="","",IF(J10+(J10*K$4)>$D10,$D10,J10+(J10*K$4))),"") -> 9.0460459 | L10: =IFERROR(IF($D10="","",IF(K10+(K10*L$4)>$D10,$D10,K10+(K10*L$4))),"") -> 10.855255 | M10: =IFERROR(IF($D10="","",IF(L10+(L10*M$4)>$D10,$D10,L10+(L10*M$4))),"") -> 12.592096 | N10: =IFERROR(IF($D10="","",IF(M10+(M10*N$4)>$D10,$D10,M10+(M10*N$4))),"") -> 14.354989 | O10: =IFERROR(IF($D10="","",IF(N10+(N10*O$4)>$D10,$D10,N10+(N10*O$4))),"") -> 16.221138 | ... BM10: =IFERROR(IF($D10="","",IF(BL10+(BL10*BM$4)>$D10,$D10,BL10+(BL10*BM$4))),"") -> 32.046943
B11: Limpeza Residencial - 8 horas | C11: =SUM(F57:BL57)/SUM($F$97:$BM$97) -> 0.041210437 | D11: =F11*'Distribuição de Modelos'!$E$50 -> 21.147901 | E11: 10 | F11: 34 | G11: =IFERROR(IF($D11="","",$G$5*$D11),"") -> 1.1419867 | H11: =IFERROR(IF($D11="","",IF(G11+(G11*H$4)>$D11,$D11,G11+(G11*H$4))),"") -> 2.2839734 | I11: =IFERROR(IF($D11="","",IF(H11+(H11*I$4)>$D11,$D11,H11+(H11*I$4))),"") -> 3.42596 | J11: =IFERROR(IF($D11="","",IF(I11+(I11*J$4)>$D11,$D11,I11+(I11*J$4))),"") -> 4.5565268 | K11: =IFERROR(IF($D11="","",IF(J11+(J11*K$4)>$D11,$D11,J11+(J11*K$4))),"") -> 5.6956585 | L11: =IFERROR(IF($D11="","",IF(K11+(K11*L$4)>$D11,$D11,K11+(K11*L$4))),"") -> 6.8347903 | M11: =IFERROR(IF($D11="","",IF(L11+(L11*M$4)>$D11,$D11,L11+(L11*M$4))),"") -> 7.9283567 | N11: =IFERROR(IF($D11="","",IF(M11+(M11*N$4)>$D11,$D11,M11+(M11*N$4))),"") -> 9.0383266 | O11: =IFERROR(IF($D11="","",IF(N11+(N11*O$4)>$D11,$D11,N11+(N11*O$4))),"") -> 10.213309 | ... BM11: =IFERROR(IF($D11="","",IF(BL11+(BL11*BM$4)>$D11,$D11,BL11+(BL11*BM$4))),"") -> 20.177705
B12: Limpeza Residencial - 2 horas | C12: =SUM(F58:BL58)/SUM($F$97:$BM$97) -> 0.015194184 | D12: =F12*'Distribuição de Modelos'!$E$50 -> 16.793922 | E12: 8 | F12: 27 | G12: =IFERROR(IF($D12="","",$G$5*$D12),"") -> 0.90687177 | H12: =IFERROR(IF($D12="","",IF(G12+(G12*H$4)>$D12,$D12,G12+(G12*H$4))),"") -> 1.8137435 | I12: =IFERROR(IF($D12="","",IF(H12+(H12*I$4)>$D12,$D12,H12+(H12*I$4))),"") -> 2.7206153 | J12: =IFERROR(IF($D12="","",IF(I12+(I12*J$4)>$D12,$D12,I12+(I12*J$4))),"") -> 3.6184184 | K12: =IFERROR(IF($D12="","",IF(J12+(J12*K$4)>$D12,$D12,J12+(J12*K$4))),"") -> 4.523023 | L12: =IFERROR(IF($D12="","",IF(K12+(K12*L$4)>$D12,$D12,K12+(K12*L$4))),"") -> 5.4276276 | M12: =IFERROR(IF($D12="","",IF(L12+(L12*M$4)>$D12,$D12,L12+(L12*M$4))),"") -> 6.296048 | N12: =IFERROR(IF($D12="","",IF(M12+(M12*N$4)>$D12,$D12,M12+(M12*N$4))),"") -> 7.1774947 | O12: =IFERROR(IF($D12="","",IF(N12+(N12*O$4)>$D12,$D12,N12+(N12*O$4))),"") -> 8.110569 | ... BM12: =IFERROR(IF($D12="","",IF(BL12+(BL12*BM$4)>$D12,$D12,BL12+(BL12*BM$4))),"") -> 16.023472
B13: Babá 4 horas | C13: =SUM(F59:BL59)/SUM($F$97:$BM$97) -> 0.018700534 | D13: =F13*'Distribuição de Modelos'!$E$50 -> 16.793922 | E13: 8 | F13: 27 | G13: =IFERROR(IF($D13="","",$G$5*$D13),"") -> 0.90687177 | H13: =IFERROR(IF($D13="","",IF(G13+(G13*H$4)>$D13,$D13,G13+(G13*H$4))),"") -> 1.8137435 | I13: =IFERROR(IF($D13="","",IF(H13+(H13*I$4)>$D13,$D13,H13+(H13*I$4))),"") -> 2.7206153 | J13: =IFERROR(IF($D13="","",IF(I13+(I13*J$4)>$D13,$D13,I13+(I13*J$4))),"") -> 3.6184184 | K13: =IFERROR(IF($D13="","",IF(J13+(J13*K$4)>$D13,$D13,J13+(J13*K$4))),"") -> 4.523023 | L13: =IFERROR(IF($D13="","",IF(K13+(K13*L$4)>$D13,$D13,K13+(K13*L$4))),"") -> 5.4276276 | M13: =IFERROR(IF($D13="","",IF(L13+(L13*M$4)>$D13,$D13,L13+(L13*M$4))),"") -> 6.296048 | N13: =IFERROR(IF($D13="","",IF(M13+(M13*N$4)>$D13,$D13,M13+(M13*N$4))),"") -> 7.1774947 | O13: =IFERROR(IF($D13="","",IF(N13+(N13*O$4)>$D13,$D13,N13+(N13*O$4))),"") -> 8.110569 | ... BM13: =IFERROR(IF($D13="","",IF(BL13+(BL13*BM$4)>$D13,$D13,BL13+(BL13*BM$4))),"") -> 16.023472
B14: Limpeza Empresarial 8 horas | C14: =SUM(F60:BL60)/SUM($F$97:$BM$97) -> 0.024241433 | D14: =F14*'Distribuição de Modelos'!$E$50 -> 12.439942 | E14: 6 | F14: 20 | G14: =IFERROR(IF($D14="","",$G$5*$D14),"") -> 0.67175687 | H14: =IFERROR(IF($D14="","",IF(G14+(G14*H$4)>$D14,$D14,G14+(G14*H$4))),"") -> 1.3435137 | I14: =IFERROR(IF($D14="","",IF(H14+(H14*I$4)>$D14,$D14,H14+(H14*I$4))),"") -> 2.0152706 | J14: =IFERROR(IF($D14="","",IF(I14+(I14*J$4)>$D14,$D14,I14+(I14*J$4))),"") -> 2.6803099 | K14: =IFERROR(IF($D14="","",IF(J14+(J14*K$4)>$D14,$D14,J14+(J14*K$4))),"") -> 3.3503874 | L14: =IFERROR(IF($D14="","",IF(K14+(K14*L$4)>$D14,$D14,K14+(K14*L$4))),"") -> 4.0204649 | M14: =IFERROR(IF($D14="","",IF(L14+(L14*M$4)>$D14,$D14,L14+(L14*M$4))),"") -> 4.6637392 | N14: =IFERROR(IF($D14="","",IF(M14+(M14*N$4)>$D14,$D14,M14+(M14*N$4))),"") -> 5.3166627 | O14: =IFERROR(IF($D14="","",IF(N14+(N14*O$4)>$D14,$D14,N14+(N14*O$4))),"") -> 6.0078289 | ... BM14: =IFERROR(IF($D14="","",IF(BL14+(BL14*BM$4)>$D14,$D14,BL14+(BL14*BM$4))),"") -> 11.869238
B15: Passadoria - 6 horas | C15: =SUM(F61:BL61)/SUM($F$97:$BM$97) -> 0.017661616 | D15: =F15*'Distribuição de Modelos'!$E$50 -> 10.573951 | E15: 5 | F15: 17 | G15: =IFERROR(IF($D15="","",$G$5*$D15),"") -> 0.57099334 | H15: =IFERROR(IF($D15="","",IF(G15+(G15*H$4)>$D15,$D15,G15+(G15*H$4))),"") -> 1.1419867 | I15: =IFERROR(IF($D15="","",IF(H15+(H15*I$4)>$D15,$D15,H15+(H15*I$4))),"") -> 1.71298 | J15: =IFERROR(IF($D15="","",IF(I15+(I15*J$4)>$D15,$D15,I15+(I15*J$4))),"") -> 2.2782634 | K15: =IFERROR(IF($D15="","",IF(J15+(J15*K$4)>$D15,$D15,J15+(J15*K$4))),"") -> 2.8478293 | L15: =IFERROR(IF($D15="","",IF(K15+(K15*L$4)>$D15,$D15,K15+(K15*L$4))),"") -> 3.4173951 | M15: =IFERROR(IF($D15="","",IF(L15+(L15*M$4)>$D15,$D15,L15+(L15*M$4))),"") -> 3.9641783 | N15: =IFERROR(IF($D15="","",IF(M15+(M15*N$4)>$D15,$D15,M15+(M15*N$4))),"") -> 4.5191633 | O15: =IFERROR(IF($D15="","",IF(N15+(N15*O$4)>$D15,$D15,N15+(N15*O$4))),"") -> 5.1066545 | ... BM15: =IFERROR(IF($D15="","",IF(BL15+(BL15*BM$4)>$D15,$D15,BL15+(BL15*BM$4))),"") -> 10.088853
B16: Limpeza Empresarial 6 horas | C16: =SUM(F62:BL62)/SUM($F$97:$BM$97) -> 0.015453914 | D16: =F16*'Distribuição de Modelos'!$E$50 -> 10.573951 | E16: 5 | F16: 17 | G16: =IFERROR(IF($D16="","",$G$5*$D16),"") -> 0.57099334 | H16: =IFERROR(IF($D16="","",IF(G16+(G16*H$4)>$D16,$D16,G16+(G16*H$4))),"") -> 1.1419867 | I16: =IFERROR(IF($D16="","",IF(H16+(H16*I$4)>$D16,$D16,H16+(H16*I$4))),"") -> 1.71298 | J16: =IFERROR(IF($D16="","",IF(I16+(I16*J$4)>$D16,$D16,I16+(I16*J$4))),"") -> 2.2782634 | K16: =IFERROR(IF($D16="","",IF(J16+(J16*K$4)>$D16,$D16,J16+(J16*K$4))),"") -> 2.8478293 | L16: =IFERROR(IF($D16="","",IF(K16+(K16*L$4)>$D16,$D16,K16+(K16*L$4))),"") -> 3.4173951 | M16: =IFERROR(IF($D16="","",IF(L16+(L16*M$4)>$D16,$D16,L16+(L16*M$4))),"") -> 3.9641783 | N16: =IFERROR(IF($D16="","",IF(M16+(M16*N$4)>$D16,$D16,M16+(M16*N$4))),"") -> 4.5191633 | O16: =IFERROR(IF($D16="","",IF(N16+(N16*O$4)>$D16,$D16,N16+(N16*O$4))),"") -> 5.1066545 | ... BM16: =IFERROR(IF($D16="","",IF(BL16+(BL16*BM$4)>$D16,$D16,BL16+(BL16*BM$4))),"") -> 10.088853
B17: Limpeza condominial 2 horas | C17: =SUM(F63:BL63)/SUM($F$97:$BM$97) -> 0.0095667085 | D17: =F17*'Distribuição de Modelos'!$E$50 -> 10.573951 | E17: 5 | F17: 17 | G17: =IFERROR(IF($D17="","",$G$5*$D17),"") -> 0.57099334 | H17: =IFERROR(IF($D17="","",IF(G17+(G17*H$4)>$D17,$D17,G17+(G17*H$4))),"") -> 1.1419867 | I17: =IFERROR(IF($D17="","",IF(H17+(H17*I$4)>$D17,$D17,H17+(H17*I$4))),"") -> 1.71298 | J17: =IFERROR(IF($D17="","",IF(I17+(I17*J$4)>$D17,$D17,I17+(I17*J$4))),"") -> 2.2782634 | K17: =IFERROR(IF($D17="","",IF(J17+(J17*K$4)>$D17,$D17,J17+(J17*K$4))),"") -> 2.8478293 | L17: =IFERROR(IF($D17="","",IF(K17+(K17*L$4)>$D17,$D17,K17+(K17*L$4))),"") -> 3.4173951 | M17: =IFERROR(IF($D17="","",IF(L17+(L17*M$4)>$D17,$D17,L17+(L17*M$4))),"") -> 3.9641783 | N17: =IFERROR(IF($D17="","",IF(M17+(M17*N$4)>$D17,$D17,M17+(M17*N$4))),"") -> 4.5191633 | O17: =IFERROR(IF($D17="","",IF(N17+(N17*O$4)>$D17,$D17,N17+(N17*O$4))),"") -> 5.1066545 | ... BM17: =IFERROR(IF($D17="","",IF(BL17+(BL17*BM$4)>$D17,$D17,BL17+(BL17*BM$4))),"") -> 10.088853
... B50: Garçom 8 horas | C50: =SUM(F96:BL96)/SUM($F$97:$BM$97) -> 0 | D50: =F50*'Distribuição de Modelos'!$E$50 -> 0 | E50: 0 | F50: 0 | G50: =IFERROR(IF($D50="","",$G$5*$D50),"") -> 0 | H50: =IFERROR(IF($D50="","",IF(G50+(G50*H$4)>$D50,$D50,G50+(G50*H$4))),"") -> 0 | I50: =IFERROR(IF($D50="","",IF(H50+(H50*I$4)>$D50,$D50,H50+(H50*I$4))),"") -> 0 | J50: =IFERROR(IF($D50="","",IF(I50+(I50*J$4)>$D50,$D50,I50+(I50*J$4))),"") -> 0 | K50: =IFERROR(IF($D50="","",IF(J50+(J50*K$4)>$D50,$D50,J50+(J50*K$4))),"") -> 0 | L50: =IFERROR(IF($D50="","",IF(K50+(K50*L$4)>$D50,$D50,K50+(K50*L$4))),"") -> 0 | M50: =IFERROR(IF($D50="","",IF(L50+(L50*M$4)>$D50,$D50,L50+(L50*M$4))),"") -> 0 | N50: =IFERROR(IF($D50="","",IF(M50+(M50*N$4)>$D50,$D50,M50+(M50*N$4))),"") -> 0 | O50: =IFERROR(IF($D50="","",IF(N50+(N50*O$4)>$D50,$D50,N50+(N50*O$4))),"") -> 0 | ... BM50: =IFERROR(IF($D50="","",IF(BL50+(BL50*BM$4)>$D50,$D50,BL50+(BL50*BM$4))),"") -> 0
B51: Faturamento Bruto | C51: Preço Médio de Venda em R$ | D51: Receita Potencial | E51: Receita Média | BO51: R$ | BP51: R$ | BQ51: R$ | BR51: R$
B52: =B6 -> Limpeza Residencial - 4 horas | C52: 160 | D52: =IFERROR(C52*D6,"") -> 66976.648 | E52: =IFERROR(AVERAGE(G52:BL52),"") -> 41679.449 | G52: =$C52*G6 -> 3616.739 | H52: =$C52*H6 -> 7233.478 | I52: =$C52*I6 -> 10850.217 | J52: =$C52*J6 -> 14430.789 | K52: =$C52*K6 -> 18038.486 | L52: =$C52*L6 -> 21646.183 | M52: =$C52*M6 -> 25109.572 | N52: =$C52*N6 -> 28624.912 | ... BM52: =$C52*BM6 -> 63903.979
B53: =B7 -> Limpeza Empresarial 4 horas | C53: 160 | D53: =IFERROR(C53*D7,"") -> 18809.192 | E53: =IFERROR(AVERAGE(G53:BL53),"") -> 11704.927 | G53: =$C53*G7 -> 1015.6964 | H53: =$C53*H7 -> 2031.3928 | I53: =$C53*I7 -> 3047.0892 | J53: =$C53*J7 -> 4052.6286 | K53: =$C53*K7 -> 5065.7857 | L53: =$C53*L7 -> 6078.9429 | M53: =$C53*M7 -> 7051.5737 | N53: =$C53*N7 -> 8038.794 | ... BM53: =$C53*BM7 -> 17946.288
B54: =B8 -> Limpeza condominial 4 horas | C54: 160 | D54: =IFERROR(C54*D8,"") -> 8061.0824 | E54: =IFERROR(AVERAGE(G54:BL54),"") -> 5016.3972 | G54: =$C54*G8 -> 435.29845 | H54: =$C54*H8 -> 870.5969 | I54: =$C54*I8 -> 1305.8954 | J54: =$C54*J8 -> 1736.8408 | K54: =$C54*K8 -> 2171.051 | L54: =$C54*L8 -> 2605.2612 | M54: =$C54*M8 -> 3022.103 | N54: =$C54*N8 -> 3445.1974 | ... BM54: =$C54*BM8 -> 7691.2664
B55: =B9 -> Passadoria - 4 horas | C55: 190 | D55: =IFERROR(C55*D9,"") -> 7918.0231 | E55: =IFERROR(AVERAGE(G55:BL55),"") -> 4927.3717 | G55: =$C55*G9 -> 427.57325 | H55: =$C55*H9 -> 855.14649 | I55: =$C55*I9 -> 1282.7197 | J55: =$C55*J9 -> 1706.0173 | K55: =$C55*K9 -> 2132.5216 | L55: =$C55*L9 -> 2559.0259 | M55: =$C55*M9 -> 2968.47 | N55: =$C55*N9 -> 3384.0558 | ... BM55: =$C55*BM9 -> 7554.7702
B56: =B10 -> Limpeza Residencial - 6 horas | C56: 210 | D56: =IFERROR(C56*D10,"") -> 7053.4471 | E56: =IFERROR(AVERAGE(G56:BL56),"") -> 4389.3476 | G56: =$C56*G10 -> 380.88614 | H56: =$C56*H10 -> 761.77229 | I56: =$C56*I10 -> 1142.6584 | J56: =$C56*J10 -> 1519.7357 | K56: =$C56*K10 -> 1899.6696 | L56: =$C56*L10 -> 2279.6036 | M56: =$C56*M10 -> 2644.3401 | N56: =$C56*N10 -> 3014.5478 | ... BM56: =$C56*BM10 -> 6729.8581
B57: =B11 -> Limpeza Residencial - 8 horas | C57: 280 | D57: =IFERROR(C57*D11,"") -> 5921.4124 | E57: =IFERROR(AVERAGE(G57:BL57),"") -> 3684.8844 | G57: =$C57*G11 -> 319.75627 | H57: =$C57*H11 -> 639.51254 | I57: =$C57*I11 -> 959.26881 | J57: =$C57*J11 -> 1275.8275 | K57: =$C57*K11 -> 1594.7844 | L57: =$C57*L11 -> 1913.7413 | M57: =$C57*M11 -> 2219.9399 | N57: =$C57*N11 -> 2530.7315 | ... BM57: =$C57*BM11 -> 5649.7574
B58: =B12 -> Limpeza Residencial - 2 horas | C58: 130 | D58: =IFERROR(C58*D12,"") -> 2183.2098 | E58: =IFERROR(AVERAGE(G58:BL58),"") -> 1358.6076 | G58: =$C58*G12 -> 117.89333 | H58: =$C58*H12 -> 235.78666 | I58: =$C58*I12 -> 353.67999 | J58: =$C58*J12 -> 470.39439 | K58: =$C58*K12 -> 587.99299 | L58: =$C58*L12 -> 705.59158 | M58: =$C58*M12 -> 818.48624 | N58: =$C58*N12 -> 933.07431 | ... BM58: =$C58*BM12 -> 2083.0513
B59: =B13 -> Babá 4 horas | C59: 160 | D59: =IFERROR(C59*D13,"") -> 2687.0275 | E59: =IFERROR(AVERAGE(G59:BL59),"") -> 1672.1324 | G59: =$C59*G13 -> 145.09948 | H59: =$C59*H13 -> 290.19897 | I59: =$C59*I13 -> 435.29845 | J59: =$C59*J13 -> 578.94694 | K59: =$C59*K13 -> 723.68367 | L59: =$C59*L13 -> 868.42041 | M59: =$C59*M13 -> 1007.3677 | N59: =$C59*N13 -> 1148.3991 | ... BM59: =$C59*BM13 -> 2563.7555
B60: =B14 -> Limpeza Empresarial 8 horas | C60: 280 | D60: =IFERROR(C60*D14,"") -> 3483.1838 | E60: =IFERROR(AVERAGE(G60:BL60),"") -> 2167.5791 | G60: =$C60*G14 -> 188.09192 | H60: =$C60*H14 -> 376.18385 | I60: =$C60*I14 -> 564.27577 | J60: =$C60*J14 -> 750.48677 | K60: =$C60*K14 -> 938.10847 | L60: =$C60*L14 -> 1125.7302 | M60: =$C60*M14 -> 1305.847 | N60: =$C60*N14 -> 1488.6656 | ... BM60: =$C60*BM14 -> 3323.3867
B61: =B15 -> Passadoria - 6 horas | C61: 240 | D61: =IFERROR(C61*D15,"") -> 2537.7482 | E61: =IFERROR(AVERAGE(G61:BL61),"") -> 1579.2362 | G61: =$C61*G15 -> 137.0384 | H61: =$C61*H15 -> 274.0768 | I61: =$C61*I15 -> 411.1152 | J61: =$C61*J15 -> 546.78322 | K61: =$C61*K15 -> 683.47903 | L61: =$C61*L15 -> 820.17483 | M61: =$C61*M15 -> 951.4028 | N61: =$C61*N15 -> 1084.5992 | ... BM61: =$C61*BM15 -> 2421.3246
B62: =B16 -> Limpeza Empresarial 6 horas | C62: 210 | D62: =IFERROR(C62*D16,"") -> 2220.5296 | E62: =IFERROR(AVERAGE(G62:BL62),"") -> 1381.8316 | G62: =$C62*G16 -> 119.9086 | H62: =$C62*H16 -> 239.8172 | I62: =$C62*I16 -> 359.7258 | J62: =$C62*J16 -> 478.43532 | K62: =$C62*K16 -> 598.04415 | L62: =$C62*L16 -> 717.65298 | M62: =$C62*M16 -> 832.47745 | N62: =$C62*N16 -> 949.0243 | ... BM62: =$C62*BM16 -> 2118.659
B63: =B17 -> Limpeza condominial 2 horas | C63: 130 | D63: =IFERROR(C63*D17,"") -> 1374.6136 | E63: =IFERROR(AVERAGE(G63:BL63),"") -> 855.41959 | G63: =$C63*G17 -> 74.229134 | H63: =$C63*H17 -> 148.45827 | I63: =$C63*I17 -> 222.6874 | J63: =$C63*J17 -> 296.17424 | K63: =$C63*K17 -> 370.21781 | L63: =$C63*L17 -> 444.26137 | M63: =$C63*M17 -> 515.34319 | N63: =$C63*N17 -> 587.49123 | ... BM63: =$C63*BM17 -> 1311.5508
... B96: =B50 -> Garçom 8 horas | C96: 280 | D96: =IFERROR(C96*D50,"") -> 0 | E96: =IFERROR(AVERAGE(G96:BL96),"") -> 0 | G96: =$C96*G50 -> 0 | H96: =$C96*H50 -> 0 | I96: =$C96*I50 -> 0 | J96: =$C96*J50 -> 0 | K96: =$C96*K50 -> 0 | L96: =$C96*L50 -> 0 | M96: =$C96*M50 -> 0 | N96: =$C96*N50 -> 0 | ... BM96: =$C96*BM50 -> 0
